Workbook

Sheet Dalu_Cenas
A1: Datums | B1: CBL Aktīvais ieguldījumu plāns | C1: CBL Universālais ieguldījumu plāns | D1: Ieguldījumu plāns "INDEXO Izaugsme 55-62" | E1: Luminor 53-58 | F1: Luminor 62-65 | G1: SEB aktīvais plāns | H1: SEB konservatīvais plāns | I1: Swedbank pensiju ieguldījumu plāns "Dinamika"
A2: 41579 | B2: 249.747 | C2: 229.834 | E2: 168.765 | F2: 158.098 | G2: 218.271 | H2: 192.906 | I2: 206.073
A3: 41582 | B3: 249.485 | C3: 229.732 | E3: 169.172 | F3: 158.279 | G3: 218.544 | H3: 192.978 | I3: 206.05
A4: 41583 | B4: 249.586 | C4: 229.875 | E4: 169.238 | F4: 158.274 | G4: 218.758 | H4: 193.288 | I4: 206.313
A5: 41584 | B5: 249.361 | C5: 229.818 | E5: 169.457 | F5: 158.289 | G5: 218.782 | H5: 193.34 | I5: 206.073
A6: 41585 | B6: 249.14 | C6: 229.776 | E6: 169.161 | F6: 158.001 | G6: 218.615 | H6: 193.249 | I6: 206.106
A7: 41586 | B7: 249.669 | C7: 229.854 | E7: 169.251 | F7: 157.956 | G7: 218.709 | H7: 193.151 | I7: 206.273
A8: 41589 | B8: 249.449 | C8: 229.776 | E8: 169.497 | F8: 158.333 | G8: 218.778 | H8: 193.085 | I8: 205.885
A9: 41590 | B9: 249.195 | C9: 229.855 | E9: 169.243 | F9: 158.038 | G9: 218.549 | H9: 193.336 | I9: 205.877
A10: 41591 | B10: 249.174 | C10: 229.622 | E10: 169.207 | F10: 157.863 | G10: 218.692 | H10: 193.23 | I10: 205.743
A11: 41592 | B11: 248.923 | C11: 229.57 | E11: 168.908 | F11: 157.692 | G11: 218.325 | H11: 193.178 | I11: 205.601
A12: 41593 | B12: 248.655 | C12: 229.507 | E12: 168.525 | F12: 157.744 | G12: 217.972 | H12: 193.054 | I12: 206.091
A13: 41598 | B13: 249.905 | C13: 230.022 | E13: 170.128 | F13: 158.199 | G13: 219.447 | H13: 193.318 | I13: 206.754
... A281: 41992 | B281: 254.03 | C281: 235.798 | E281: 176.252 | F281: 163.602 | G281: 225.051 | H281: 197.923 | I281: 217.263
A282: 41995 | B282: 255.561 | C282: 236.268 | E282: 178.459 | F282: 163.57 | G282: 228.152 | H282: 198.103
A283: 41996 | B283: 256.186 | C283: 236.816 | E283: 179.508 | F283: 163.811 | G283: 229.188 | H283: 198.282 | I283: 218.412
A284: 42002 | B284: 256.888 | C284: 237.042 | E284: 179.994 | F284: 163.958 | G284: 230.049 | H284: 198.36 | I284: 218.9
A285: 42003 | B285: 256.795 | C285: 237.022 | E285: 180.512 | F285: 164.032 | G285: 230.516 | H285: 198.481 | I285: 219.035
A286: 42004 | B286: 257.211 | C286: 237.307 | E286: 180.702 | F286: 164.238 | G286: 230.564 | H286: 198.486 | I286: 218.899
A287: 42009 | B287: 257.15 | C287: 237.247 | E287: 181.024 | F287: 164.169 | G287: 230.571 | H287: 198.481 | I287: 218.778
A288: 42010 | B288: 257.019 | C288: 237.671 | E288: 180.69 | F288: 164.493 | G288: 230.706 | H288: 198.908
A289: 42011 | B289: 256.02 | C289: 237.508 | E289: 179.651 | F289: 164.511 | G289: 230.201 | H289: 199.064 | I289: 217.884
A290: 42012 | B290: 255.736 | C290: 237.621 | E290: 178.955 | F290: 164.555 | G290: 229.63 | H290: 199.359 | I290: 218.42
A291: 42013 | B291: 256.124 | C291: 237.959 | E291: 179.98 | F291: 164.635 | G291: 230.329 | H291: 199.649 | I291: 219.384
A292: 42016 | B292: 257.103 | C292: 238.091 | E292: 181.882 | F292: 164.972 | G292: 232.019 | H292: 199.684 | I292: 219.364
A293: 42017 | B293: 257.596 | C293: 238.247 | E293: 181.239 | F293: 165.345 | G293: 232.165 | H293: 199.823 | I293: 219.362
A294: 42018 | B294: 257.642 | C294: 238.305 | E294: 181.234 | F294: 165.373 | G294: 231.787 | H294: 199.949 | I294: 220.282
A295: 42019 | B295: 258.508 | C295: 238.53 | E295: 182.206 | F295: 165.436 | G295: 232.465 | H295: 200 | I295: 219.627
A296: 42020 | B296: 258.249 | C296: 238.847 | E296: 180.835 | F296: 165.623 | G296: 231.775 | H296: 200.333 | I296: 220.507
A297: 42023 | B297: 259.289 | C297: 239.279 | E297: 182.536 | F297: 165.888 | G297: 233.071 | H297: 200.576 | I297: 221.282
A298: 42024 | B298: 260.016 | C298: 239.56 | E298: 183.105 | F298: 165.999 | G298: 233.634 | H298: 200.813 | I298: 221.784
A299: 42025 | B299: 260.642 | C299: 239.578 | E299: 182.956 | F299: 165.899 | G299: 234.29 | H299: 201.083 | I299: 222.008
A300: 42026 | B300: 260.88 | C300: 239.631 | E300: 183.416 | F300: 165.994 | G300: 234.439 | H300: 201.05 | I300: 222.613
... A368: 42124 | B368: 270.606 | C368: 244.091 | E368: 195.404 | F368: 167.967 | G368: 247.846 | H368: 203.453 | I368: 231.874
A369: 42129 | B369: 269.478 | C369: 243.438 | E369: 192.114 | F369: 166.773 | G369: 246.23 | H369: 202.974
A370: 42130 | B370: 268.703 | C370: 243.024 | E370: 192.751 | F370: 166.577 | G370: 245.412 | H370: 202.928 | I370: 230.189
A371: 42131 | B371: 268.077 | C371: 242.589 | E371: 191.373 | F371: 166.188 | G371: 244.565 | H371: 202.292 | I371: 228.718
A372: 42132 | B372: 267.003 | C372: 242.138 | E372: 190.035 | F372: 165.78 | G372: 243.018 | H372: 202.007 | I372: 228.421
A373: 42135 | B373: 266.782 | C373: 242.282 | E373: 190.026 | F373: 165.724 | G373: 242.895 | H373: 201.88 | I373: 229.994
A374: 42136 | B374: 268.271 | C374: 242.635 | E374: 191.98 | F374: 166.173 | G374: 244.715 | H374: 202.042 | I374: 230.125
...

Sheet Izmainas
A1: Datums | B1: CBL Aktīvais ieguldījumu plāns | C1: CBL Universālais ieguldījumu plāns | D1: Ieguldījumu plāns "INDEXO Izaugsme 55-62" | E1: Luminor 53-58 | F1: Luminor 62-65 | G1: SEB aktīvais plāns | H1: SEB konservatīvais plāns | I1: Swedbank pensiju ieguldījumu plāns "Dinamika"
A2: 41579 | B2: 0 | C2: 0 | E2: 0 | F2: 0 | G2: 0 | H2: 0 | I2: 0
A3: 41582 | B3: -0.1 | C3: -0.04 | E3: 0.24 | F3: 0.11 | G3: 0.13 | H3: 0.04 | I3: -0.01
A4: 41583 | B4: -0.06 | C4: 0.02 | E4: 0.28 | F4: 0.11 | G4: 0.22 | H4: 0.2 | I4: 0.12
A5: 41584 | B5: -0.15 | C5: -0.01 | E5: 0.41 | F5: 0.12 | G5: 0.23 | H5: 0.23 | I5: 0
A6: 41585 | B6: -0.24 | C6: -0.03 | E6: 0.23 | F6: -0.06 | G6: 0.16 | H6: 0.18 | I6: 0.02
A7: 41586 | B7: -0.03 | C7: 0.01 | E7: 0.29 | F7: -0.09 | G7: 0.2 | H7: 0.13 | I7: 0.1
A8: 41589 | B8: -0.12 | C8: -0.03 | E8: 0.43 | F8: 0.15 | G8: 0.23 | H8: 0.09 | I8: -0.09
A9: 41590 | B9: -0.22 | C9: 0.01 | E9: 0.28 | F9: -0.04 | G9: 0.13 | H9: 0.22 | I9: -0.09
A10: 41591 | B10: -0.23 | C10: -0.09 | E10: 0.26 | F10: -0.15 | G10: 0.19 | H10: 0.17 | I10: -0.16
A11: 41592 | B11: -0.33 | C11: -0.12 | E11: 0.08 | F11: -0.26 | G11: 0.03 | H11: 0.14 | I11: -0.23
A12: 41593 | B12: -0.44 | C12: -0.14 | E12: -0.14 | F12: -0.22 | G12: -0.14 | H12: 0.08 | I12: 0.01
A13: 41598 | B13: 0.06 | C13: 0.08 | E13: 0.81 | F13: 0.06 | G13: 0.54 | H13: 0.21 | I13: 0.33
... A281: 41992 | B281: 1.72 | C281: 2.59 | E281: 4.44 | F281: 3.48 | G281: 3.11 | H281: 2.6 | I281: 5.43
A282: 41995 | B282: 2.33 | C282: 2.8 | E282: 5.74 | F282: 3.46 | G282: 4.53 | H282: 2.69
A283: 41996 | B283: 2.58 | C283: 3.04 | E283: 6.37 | F283: 3.61 | G283: 5 | H283: 2.79 | I283: 5.99
A284: 42002 | B284: 2.86 | C284: 3.14 | E284: 6.65 | F284: 3.71 | G284: 5.4 | H284: 2.83 | I284: 6.22
A285: 42003 | B285: 2.82 | C285: 3.13 | E285: 6.96 | F285: 3.75 | G285: 5.61 | H285: 2.89 | I285: 6.29
A286: 42004 | B286: 2.99 | C286: 3.25 | E286: 7.07 | F286: 3.88 | G286: 5.63 | H286: 2.89 | I286: 6.22
A287: 42009 | B287: 2.96 | C287: 3.23 | E287: 7.26 | F287: 3.84 | G287: 5.64 | H287: 2.89 | I287: 6.17
A288: 42010 | B288: 2.91 | C288: 3.41 | E288: 7.07 | F288: 4.05 | G288: 5.7 | H288: 3.11
A289: 42011 | B289: 2.51 | C289: 3.34 | E289: 6.45 | F289: 4.06 | G289: 5.47 | H289: 3.19 | I289: 5.73
A290: 42012 | B290: 2.4 | C290: 3.39 | E290: 6.04 | F290: 4.08 | G290: 5.2 | H290: 3.35 | I290: 5.99
A291: 42013 | B291: 2.55 | C291: 3.53 | E291: 6.65 | F291: 4.13 | G291: 5.52 | H291: 3.5 | I291: 6.46
A292: 42016 | B292: 2.95 | C292: 3.59 | E292: 7.77 | F292: 4.35 | G292: 6.3 | H292: 3.51 | I292: 6.45
A293: 42017 | B293: 3.14 | C293: 3.66 | E293: 7.39 | F293: 4.58 | G293: 6.37 | H293: 3.59 | I293: 6.45
A294: 42018 | B294: 3.16 | C294: 3.69 | E294: 7.39 | F294: 4.6 | G294: 6.19 | H294: 3.65 | I294: 6.9
A295: 42019 | B295: 3.51 | C295: 3.78 | E295: 7.96 | F295: 4.64 | G295: 6.5 | H295: 3.68 | I295: 6.58
A296: 42020 | B296: 3.4 | C296: 3.92 | E296: 7.15 | F296: 4.76 | G296: 6.19 | H296: 3.85 | I296: 7
A297: 42023 | B297: 3.82 | C297: 4.11 | E297: 8.16 | F297: 4.93 | G297: 6.78 | H297: 3.98 | I297: 7.38
A298: 42024 | B298: 4.11 | C298: 4.23 | E298: 8.5 | F298: 5 | G298: 7.04 | H298: 4.1 | I298: 7.62
A299: 42025 | B299: 4.36 | C299: 4.24 | E299: 8.41 | F299: 4.93 | G299: 7.34 | H299: 4.24 | I299: 7.73
A300: 42026 | B300: 4.46 | C300: 4.26 | E300: 8.68 | F300: 4.99 | G300: 7.41 | H300: 4.22 | I300: 8.03
... A368: 42124 | B368: 8.35 | C368: 6.2 | E368: 15.78 | F368: 6.24 | G368: 13.55 | H368: 5.47 | I368: 12.52
A369: 42129 | B369: 7.9 | C369: 5.92 | E369: 13.84 | F369: 5.49 | G369: 12.81 | H369: 5.22
A370: 42130 | B370: 7.59 | C370: 5.74 | E370: 14.21 | F370: 5.36 | G370: 12.43 | H370: 5.2 | I370: 11.7
A371: 42131 | B371: 7.34 | C371: 5.55 | E371: 13.4 | F371: 5.12 | G371: 12.05 | H371: 4.87 | I371: 10.99
A372: 42132 | B372: 6.91 | C372: 5.35 | E372: 12.6 | F372: 4.86 | G372: 11.34 | H372: 4.72 | I372: 10.84
A373: 42135 | B373: 6.82 | C373: 5.42 | E373: 12.6 | F373: 4.82 | G373: 11.28 | H373: 4.65 | I373: 11.61
A374: 42136 | B374: 7.42 | C374: 5.57 | E374: 13.76 | F374: 5.11 | G374: 12.12 | H374: 4.74 | I374: 11.67
...

Sheet KIK
A1: Pensiju plāns | B1: KIK (gadā, %) | C1: KIK kā decimāldaļa
A2: CBL Aktīvais ieguldījumu plāns | B2: 0.0061 | C2: 0.0061
A3: CBL Universālais ieguldījumu plāns | B3: 0.006 | C3: 0.006
A4: Ieguldījumu plāns "INDEXO Izaugsme 55-62" | B4: 0.00413 | C4: 0.00413
A5: Luminor 53-58 | B5: 0.0112 | C5: 0.0112
A6: Luminor 62-65 | B6: 0.004727 | C6: 0.004727
A7: SEB aktīvais plāns | B7: 0.0041 | C7: 0.0041
A8: SEB konservatīvais plāns | B8: 0.0034 | C8: 0.0034
A9: Swedbank pensiju ieguldījumu plāns "Dinamika" | B9: 0.00347 | C9: 0.00347

Sheet Mani_Dati
A1: Personas bruto darba alga vismaz pēdējos 5 gados
A2: No | B2: Līdz | C2: Alga
A3: =DATE(2017,1,1) -> 42736 | B3: =DATE(2019,8,1) -> 43678 | C3: 800
A4: =DATE(2019,8,2) -> 43679 | B4: =DATE(2019,12,31) -> 43830 | C4: 1500
A5: =DATE(2020,1,1) -> 43831 | B5: =DATE(2022,10,1) -> 44835 | C5: 1000
A7: Pensiju fonda nosaukums (izritinošā izvēle) | B7: Ieguldījumu plāns "INDEXO Izaugsme 55-62"
A8: KIK % | B8: =INDEX(KIK!$B$2:$B$9, MATCH(Mani_Dati!$B$7, KIK!$A$2:$A$9, 0)) -> 0.00413
A9: Sākuma datums | B9: {=INDEX(Dalu_Cenas!$A$2:$A$20000, MATCH(TRUE, INDEX( INDEX(Dalu_Cenas!$B$2:$I$20000,0, MATCH(B7, Dalu_Cenas!$B$1:$I$1,0))>0, 0), 0))} -> 42919
A10: Uzkrātais kapitāls uz sākuma datumu (EUR) | B10: 2000

Sheet Kalkulators
A1: Sākuma uzkrājums 01.01.2018 | C1: =Mani_Dati!B10 -> 2000 | D1: =D3 -> 101.682 | E1: =IF(D1=0,0,C1/D1) -> 19.669165 | F1: =SUM($E1:E$2) -> 19.669165 | G1: =Mani_Dati!B8 -> 0.00413
A2: Datums | B2: Bruto alga | C2: Iemaksa 2. līm. 6% | D2: Daļas cena | E2: Iegādātās daļas | F2: Daļas kopā | G2: Pārvaldīšanas izdevumi (KIK%/12) | H2: Daļas pēc izdevumiem | I2: Uzkrājums (daļas × cena)
A3: =DATE(2018,1,1) -> 43101 | B3: {=INDEX(Mani_Dati!$C$3:$C$5, MATCH(1, (A3>=Mani_Dati!$A$3:$A$5)*(A3<=Mani_Dati!$B$3:$B$5), 0))} -> 800 | C3: =B3*0.06 -> 48 | D3: =INDEX(Dalu_Cenas!$A:$I, MATCH(A3, Dalu_Cenas!$A:$A, 1), MATCH(Mani_Dati!$B$7, Dalu_Cenas!$1:$1, 0)) -> 101.682 | E3: =IF(D3=0,0,C3/D3) -> 0.47205995 | F3: =F$1 + SUM($E$2:E3) -> 20.141225 | G3: =F3 * ($G$1/12) -> 0.0069319381 | H3: =F3 - G3 -> 20.134293 | I3: =H3 * D3 -> 2047.2951
A4: =EDATE(A3,1) -> 43132 | B4: {=INDEX(Mani_Dati!$C$3:$C$5, MATCH(1, (A4>=Mani_Dati!$A$3:$A$5)*(A4<=Mani_Dati!$B$3:$B$5), 0))} -> 800 | C4: =B4*0.06 -> 48 | D4: =INDEX(Dalu_Cenas!$A:$I, MATCH(A4, Dalu_Cenas!$A:$A, 1), MATCH(Mani_Dati!$B$7, Dalu_Cenas!$1:$1, 0)) -> 101.447 | E4: =IF(D4=0,0,C4/D4) -> 0.47315347 | F4: =F$1 + SUM($E$2:E4) -> 20.614378 | G4: =F4 * ($G$1/12) -> 0.0070947818 | H4: =F4 - G4 -> 20.607283 | I4: =H4 * D4 -> 2090.5471
A5: =EDATE(A4,1) -> 43160 | B5: {=INDEX(Mani_Dati!$C$3:$C$5, MATCH(1, (A5>=Mani_Dati!$A$3:$A$5)*(A5<=Mani_Dati!$B$3:$B$5), 0))} -> 800 | C5: =B5*0.06 -> 48 | D5: =INDEX(Dalu_Cenas!$A:$I, MATCH(A5, Dalu_Cenas!$A:$A, 1), MATCH(Mani_Dati!$B$7, Dalu_Cenas!$1:$1, 0)) -> 100.801 | E5: =IF(D5=0,0,C5/D5) -> 0.47618575 | F5: =F$1 + SUM($E$2:E5) -> 21.090564 | G5: =F5 * ($G$1/12) -> 0.007258669 | H5: =F5 - G5 -> 21.083305 | I5: =H5 * D5 -> 2125.2182
A6: =EDATE(A5,1) -> 43191 | B6: {=INDEX(Mani_Dati!$C$3:$C$5, MATCH(1, (A6>=Mani_Dati!$A$3:$A$5)*(A6<=Mani_Dati!$B$3:$B$5), 0))} -> 800 | C6: =B6*0.06 -> 48 | D6: =INDEX(Dalu_Cenas!$A:$I, MATCH(A6, Dalu_Cenas!$A:$A, 1), MATCH(Mani_Dati!$B$7, Dalu_Cenas!$1:$1, 0)) -> 98.54 | E6: =IF(D6=0,0,C6/D6) -> 0.48711183 | F6: =F$1 + SUM($E$2:E6) -> 21.577676 | G6: =F6 * ($G$1/12) -> 0.0074263167 | H6: =F6 - G6 -> 21.570249 | I6: =H6 * D6 -> 2125.5324
A7: =EDATE(A6,1) -> 43221 | B7: {=INDEX(Mani_Dati!$C$3:$C$5, MATCH(1, (A7>=Mani_Dati!$A$3:$A$5)*(A7<=Mani_Dati!$B$3:$B$5), 0))} -> 800 | C7: =B7*0.06 -> 48 | D7: =INDEX(Dalu_Cenas!$A:$I, MATCH(A7, Dalu_Cenas!$A:$A, 1), MATCH(Mani_Dati!$B$7, Dalu_Cenas!$1:$1, 0)) -> 99.903 | E7: =IF(D7=0,0,C7/D7) -> 0.48046605 | F7: =F$1 + SUM($E$2:E7) -> 22.058142 | G7: =F7 * ($G$1/12) -> 0.0075916771 | H7: =F7 - G7 -> 22.05055 | I7: =H7 * D7 -> 2202.9161
A8: =EDATE(A7,1) -> 43252 | B8: {=INDEX(Mani_Dati!$C$3:$C$5, MATCH(1, (A8>=Mani_Dati!$A$3:$A$5)*(A8<=Mani_Dati!$B$3:$B$5), 0))} -> 800 | C8: =B8*0.06 -> 48 | D8: =INDEX(Dalu_Cenas!$A:$I, MATCH(A8, Dalu_Cenas!$A:$A, 1), MATCH(Mani_Dati!$B$7, Dalu_Cenas!$1:$1, 0)) -> 103.132 | E8: =IF(D8=0,0,C8/D8) -> 0.46542295 | F8: =F$1 + SUM($E$2:E8) -> 22.523565 | G8: =F8 * ($G$1/12) -> 0.0077518602 | H8: =F8 - G8 -> 22.515813 | I8: =H8 * D8 -> 2322.1008
A9: =EDATE(A8,1) -> 43282 | B9: {=INDEX(Mani_Dati!$C$3:$C$5, MATCH(1, (A9>=Mani_Dati!$A$3:$A$5)*(A9<=Mani_Dati!$B$3:$B$5), 0))} -> 800 | C9: =B9*0.06 -> 48 | D9: =INDEX(Dalu_Cenas!$A:$I, MATCH(A9, Dalu_Cenas!$A:$A, 1), MATCH(Mani_Dati!$B$7, Dalu_Cenas!$1:$1, 0)) -> 102.841 | E9: =IF(D9=0,0,C9/D9) -> 0.46673992 | F9: =F$1 + SUM($E$2:E9) -> 22.990305 | G9: =F9 * ($G$1/12) -> 0.0079124965 | H9: =F9 - G9 -> 22.982392 | I9: =H9 * D9 -> 2363.5322
A10: =EDATE(A9,1) -> 43313 | B10: {=INDEX(Mani_Dati!$C$3:$C$5, MATCH(1, (A10>=Mani_Dati!$A$3:$A$5)*(A10<=Mani_Dati!$B$3:$B$5), 0))} -> 800 | C10: =B10*0.06 -> 48 | D10: =INDEX(Dalu_Cenas!$A:$I, MATCH(A10, Dalu_Cenas!$A:$A, 1), MATCH(Mani_Dati!$B$7, Dalu_Cenas!$1:$1, 0)) -> 103.815 | E10: =IF(D10=0,0,C10/D10) -> 0.46236093 | F10: =F$1 + SUM($E$2:E10) -> 23.452666 | G10: =F10 * ($G$1/12) -> 0.0080716257 | H10: =F10 - G10 -> 23.444594 | I10: =H10 * D10 -> 2433.9005
A11: =EDATE(A10,1) -> 43344 | B11: {=INDEX(Mani_Dati!$C$3:$C$5, MATCH(1, (A11>=Mani_Dati!$A$3:$A$5)*(A11<=Mani_Dati!$B$3:$B$5), 0))} -> 800 | C11: =B11*0.06 -> 48 | D11: =INDEX(Dalu_Cenas!$A:$I, MATCH(A11, Dalu_Cenas!$A:$A, 1), MATCH(Mani_Dati!$B$7, Dalu_Cenas!$1:$1, 0)) -> 104.843 | E11: =IF(D11=0,0,C11/D11) -> 0.45782742 | F11: =F$1 + SUM($E$2:E11) -> 23.910493 | G11: =F11 * ($G$1/12) -> 0.0082291946 | H11: =F11 - G11 -> 23.902264 | I11: =H11 * D11 -> 2505.985
A12: =EDATE(A11,1) -> 43374 | B12: {=INDEX(Mani_Dati!$C$3:$C$5, MATCH(1, (A12>=Mani_Dati!$A$3:$A$5)*(A12<=Mani_Dati!$B$3:$B$5), 0))} -> 800 | C12: =B12*0.06 -> 48 | D12: =INDEX(Dalu_Cenas!$A:$I, MATCH(A12, Dalu_Cenas!$A:$A, 1), MATCH(Mani_Dati!$B$7, Dalu_Cenas!$1:$1, 0)) -> 104.829 | E12: =IF(D12=0,0,C12/D12) -> 0.45788856 | F12: =F$1 + SUM($E$2:E12) -> 24.368381 | G12: =F12 * ($G$1/12) -> 0.0083867846 | H12: =F12 - G12 -> 24.359995 | I12: =H12 * D12 -> 2553.6339
A13: =EDATE(A12,1) -> 43405 | B13: {=INDEX(Mani_Dati!$C$3:$C$5, MATCH(1, (A13>=Mani_Dati!$A$3:$A$5)*(A13<=Mani_Dati!$B$3:$B$5), 0))} -> 800 | C13: =B13*0.06 -> 48 | D13: =INDEX(Dalu_Cenas!$A:$I, MATCH(A13, Dalu_Cenas!$A:$A, 1), MATCH(Mani_Dati!$B$7, Dalu_Cenas!$1:$1, 0)) -> 102.156 | E13: =IF(D13=0,0,C13/D13) -> 0.46986961 | F13: =F$1 + SUM($E$2:E13) -> 24.838251 | G13: =F13 * ($G$1/12) -> 0.0085484981 | H13: =F13 - G13 -> 24.829703 | I13: =H13 * D13 -> 2536.5031
A14: =EDATE(A13,1) -> 43435 | B14: {=INDEX(Mani_Dati!$C$3:$C$5, MATCH(1, (A14>=Mani_Dati!$A$3:$A$5)*(A14<=Mani_Dati!$B$3:$B$5), 0))} -> 800 | C14: =B14*0.06 -> 48 | D14: =INDEX(Dalu_Cenas!$A:$I, MATCH(A14, Dalu_Cenas!$A:$A, 1), MATCH(Mani_Dati!$B$7, Dalu_Cenas!$1:$1, 0)) -> 102.924 | E14: =IF(D14=0,0,C14/D14) -> 0.46636353 | F14: =F$1 + SUM($E$2:E14) -> 25.304615 | G14: =F14 * ($G$1/12) -> 0.0087090049 | H14: =F14 - G14 -> 25.295906 | I14: =H14 * D14 -> 2603.5558
A15: =EDATE(A14,1) -> 43466 | B15: {=INDEX(Mani_Dati!$C$3:$C$5, MATCH(1, (A15>=Mani_Dati!$A$3:$A$5)*(A15<=Mani_Dati!$B$3:$B$5), 0))} -> 800 | C15: =B15*0.06 -> 48 | D15: =INDEX(Dalu_Cenas!$A:$I, MATCH(A15, Dalu_Cenas!$A:$A, 1), MATCH(Mani_Dati!$B$7, Dalu_Cenas!$1:$1, 0)) -> 99.114 | E15: =IF(D15=0,0,C15/D15) -> 0.48429082 | F15: =F$1 + SUM($E$2:E15) -> 25.788905 | G15: =F15 * ($G$1/12) -> 0.0088756816 | H15: =F15 - G15 -> 25.78003 | I15: =H15 * D15 -> 2555.1619
... A49: =EDATE(A48,1) -> 44501 | B49: {=INDEX(Mani_Dati!$C$3:$C$5, MATCH(1, (A49>=Mani_Dati!$A$3:$A$5)*(A49<=Mani_Dati!$B$3:$B$5), 0))} -> 1000 | C49: =B49*0.06 -> 60 | D49: =INDEX(Dalu_Cenas!$A:$I, MATCH(A49, Dalu_Cenas!$A:$A, 1), MATCH(Mani_Dati!$B$7, Dalu_Cenas!$1:$1, 0)) -> 132.919 | E49: =IF(D49=0,0,C49/D49) -> 0.45140273 | F49: =F$1 + SUM($E$2:E49) -> 43.602101 | G49: =F49 * ($G$1/12) -> 0.01500639 | H49: =F49 - G49 -> 43.587094 | I49: =H49 * D49 -> 5793.553
A50: =EDATE(A49,1) -> 44531 | B50: {=INDEX(Mani_Dati!$C$3:$C$5, MATCH(1, (A50>=Mani_Dati!$A$3:$A$5)*(A50<=Mani_Dati!$B$3:$B$5), 0))} -> 1000 | C50: =B50*0.06 -> 60 | D50: =INDEX(Dalu_Cenas!$A:$I, MATCH(A50, Dalu_Cenas!$A:$A, 1), MATCH(Mani_Dati!$B$7, Dalu_Cenas!$1:$1, 0)) -> 134.748 | E50: =IF(D50=0,0,C50/D50) -> 0.44527563 | F50: =F$1 + SUM($E$2:E50) -> 44.047376 | G50: =F50 * ($G$1/12) -> 0.015159639 | H50: =F50 - G50 -> 44.032216 | I50: =H50 * D50 -> 5933.2531 | L50: KOPĀ | M50: Mēnešu skaits | N50: Iemaksas | O50: Vidējā mēneša iemaksa | P50: Pārvaldītāja atskaitījumi | Q50: Daļas kopā | R50: Daļas kopā(ROUGH) | S50: Izdevumu daļas | T50: Ieguvums no pensijas | U50: Efektīvā % likme
A51: =EDATE(A50,1) -> 44562 | B51: {=INDEX(Mani_Dati!$C$3:$C$5, MATCH(1, (A51>=Mani_Dati!$A$3:$A$5)*(A51<=Mani_Dati!$B$3:$B$5), 0))} -> 1000 | C51: =B51*0.06 -> 60 | D51: =INDEX(Dalu_Cenas!$A:$I, MATCH(A51, Dalu_Cenas!$A:$A, 1), MATCH(Mani_Dati!$B$7, Dalu_Cenas!$1:$1, 0)) -> 136.398 | E51: =IF(D51=0,0,C51/D51) -> 0.43988915 | F51: =F$1 + SUM($E$2:E51) -> 44.487265 | G51: =F51 * ($G$1/12) -> 0.015311034 | H51: =F51 - G51 -> 44.471954 | I51: =H51 * D51 -> 6065.8856 | L51: Ieskaitot uzkrājumu | M51: =A61 -> 58 | N51: =SUM(C1:C60) -> 5360 | O51: =AVERAGE(C3:C60) -> 57.931034 | P51: =(SUM(H2:H60)-SUM(F3:F60))*D60 -> -82.92941 | Q51: =H60 -> 48.725814 | R51: =E61 -> 48.742589 | S51: =Q51-R51 -> -0.016775575 | T51: =I60 - SUM(C1:C60) -> 494.60144 | U51: =XIRR(B75:B133, A75:A133) -> 0.02691581
A52: =EDATE(A51,1) -> 44593 | B52: {=INDEX(Mani_Dati!$C$3:$C$5, MATCH(1, (A52>=Mani_Dati!$A$3:$A$5)*(A52<=Mani_Dati!$B$3:$B$5), 0))} -> 1000 | C52: =B52*0.06 -> 60 | D52: =INDEX(Dalu_Cenas!$A:$I, MATCH(A52, Dalu_Cenas!$A:$A, 1), MATCH(Mani_Dati!$B$7, Dalu_Cenas!$1:$1, 0)) -> 132.164 | E52: =IF(D52=0,0,C52/D52) -> 0.45398142 | F52: =F$1 + SUM($E$2:E52) -> 44.941247 | G52: =F52 * ($G$1/12) -> 0.015467279 | H52: =F52 - G52 -> 44.925779 | I52: =H52 * D52 -> 5937.5707 | P52: vai
A53: =EDATE(A52,1) -> 44621 | B53: {=INDEX(Mani_Dati!$C$3:$C$5, MATCH(1, (A53>=Mani_Dati!$A$3:$A$5)*(A53<=Mani_Dati!$B$3:$B$5), 0))} -> 1000 | C53: =B53*0.06 -> 60 | D53: =INDEX(Dalu_Cenas!$A:$I, MATCH(A53, Dalu_Cenas!$A:$A, 1), MATCH(Mani_Dati!$B$7, Dalu_Cenas!$1:$1, 0)) -> 129.404 | E53: =IF(D53=0,0,C53/D53) -> 0.46366418 | F53: =F$1 + SUM($E$2:E53) -> 45.404911 | G53: =F53 * ($G$1/12) -> 0.015626857 | H53: =F53 - G53 -> 45.389284 | I53: =H53 * D53 -> 5873.5549 | N53: =SUM(C3:C60) -> 3360 | P53: =C133 -> -81.596569
A54: =EDATE(A53,1) -> 44652 | B54: {=INDEX(Mani_Dati!$C$3:$C$5, MATCH(1, (A54>=Mani_Dati!$A$3:$A$5)*(A54<=Mani_Dati!$B$3:$B$5), 0))} -> 1000 | C54: =B54*0.06 -> 60 | D54: =INDEX(Dalu_Cenas!$A:$I, MATCH(A54, Dalu_Cenas!$A:$A, 1), MATCH(Mani_Dati!$B$7, Dalu_Cenas!$1:$1, 0)) -> 131.58 | E54: =IF(D54=0,0,C54/D54) -> 0.45599635 | F54: =F$1 + SUM($E$2:E54) -> 45.860907 | G54: =F54 * ($G$1/12) -> 0.015783796 | H54: =F54 - G54 -> 45.845123 | I54: =H54 * D54 -> 6032.3013
A55: =EDATE(A54,1) -> 44682 | B55: {=INDEX(Mani_Dati!$C$3:$C$5, MATCH(1, (A55>=Mani_Dati!$A$3:$A$5)*(A55<=Mani_Dati!$B$3:$B$5), 0))} -> 1000 | C55: =B55*0.06 -> 60 | D55: =INDEX(Dalu_Cenas!$A:$I, MATCH(A55, Dalu_Cenas!$A:$A, 1), MATCH(Mani_Dati!$B$7, Dalu_Cenas!$1:$1, 0)) -> 128.723 | E55: =IF(D55=0,0,C55/D55) -> 0.46611717 | F55: =F$1 + SUM($E$2:E55) -> 46.327024 | G55: =F55 * ($G$1/12) -> 0.015944218 | H55: =F55 - G55 -> 46.31108 | I55: =H55 * D55 -> 5961.3012
A56: =EDATE(A55,1) -> 44713 | B56: {=INDEX(Mani_Dati!$C$3:$C$5, MATCH(1, (A56>=Mani_Dati!$A$3:$A$5)*(A56<=Mani_Dati!$B$3:$B$5), 0))} -> 1000 | C56: =B56*0.06 -> 60 | D56: =INDEX(Dalu_Cenas!$A:$I, MATCH(A56, Dalu_Cenas!$A:$A, 1), MATCH(Mani_Dati!$B$7, Dalu_Cenas!$1:$1, 0)) -> 126.454 | E56: =IF(D56=0,0,C56/D56) -> 0.47448084 | F56: =F$1 + SUM($E$2:E56) -> 46.801505 | G56: =F56 * ($G$1/12) -> 0.016107518 | H56: =F56 - G56 -> 46.785398 | I56: =H56 * D56 -> 5916.2007
A57: =EDATE(A56,1) -> 44743 | B57: {=INDEX(Mani_Dati!$C$3:$C$5, MATCH(1, (A57>=Mani_Dati!$A$3:$A$5)*(A57<=Mani_Dati!$B$3:$B$5), 0))} -> 1000 | C57: =B57*0.06 -> 60 | D57: =INDEX(Dalu_Cenas!$A:$I, MATCH(A57, Dalu_Cenas!$A:$A, 1), MATCH(Mani_Dati!$B$7, Dalu_Cenas!$1:$1, 0)) -> 120.45 | E57: =IF(D57=0,0,C57/D57) -> 0.498132 | F57: =F$1 + SUM($E$2:E57) -> 47.299637 | G57: =F57 * ($G$1/12) -> 0.016278958 | H57: =F57 - G57 -> 47.283358 | I57: =H57 * D57 -> 5695.2805
A58: =EDATE(A57,1) -> 44774 | B58: {=INDEX(Mani_Dati!$C$3:$C$5, MATCH(1, (A58>=Mani_Dati!$A$3:$A$5)*(A58<=Mani_Dati!$B$3:$B$5), 0))} -> 1000 | C58: =B58*0.06 -> 60 | D58: =INDEX(Dalu_Cenas!$A:$I, MATCH(A58, Dalu_Cenas!$A:$A, 1), MATCH(Mani_Dati!$B$7, Dalu_Cenas!$1:$1, 0)) -> 128.83 | E58: =IF(D58=0,0,C58/D58) -> 0.46573003 | F58: =F$1 + SUM($E$2:E58) -> 47.765367 | G58: =F58 * ($G$1/12) -> 0.016439247 | H58: =F58 - G58 -> 47.748928 | I58: =H58 * D58 -> 6151.4944
A59: =EDATE(A58,1) -> 44805 | B59: {=INDEX(Mani_Dati!$C$3:$C$5, MATCH(1, (A59>=Mani_Dati!$A$3:$A$5)*(A59<=Mani_Dati!$B$3:$B$5), 0))} -> 1000 | C59: =B59*0.06 -> 60 | D59: =INDEX(Dalu_Cenas!$A:$I, MATCH(A59, Dalu_Cenas!$A:$A, 1), MATCH(Mani_Dati!$B$7, Dalu_Cenas!$1:$1, 0)) -> 125.559 | E59: =IF(D59=0,0,C59/D59) -> 0.477863 | F59: =F$1 + SUM($E$2:E59) -> 48.24323 | G59: =F59 * ($G$1/12) -> 0.016603712 | H59: =F59 - G59 -> 48.226627 | I59: =H59 * D59 -> 6055.287
A60: =EDATE(A59,1) -> 44835 | B60: {=INDEX(Mani_Dati!$C$3:$C$5, MATCH(1, (A60>=Mani_Dati!$A$3:$A$5)*(A60<=Mani_Dati!$B$3:$B$5), 0))} -> 1000 | C60: =B60*0.06 -> 60 | D60: =INDEX(Dalu_Cenas!$A:$I, MATCH(A60, Dalu_Cenas!$A:$A, 1), MATCH(Mani_Dati!$B$7, Dalu_Cenas!$1:$1, 0)) -> 120.154 | E60: =IF(D60=0,0,C60/D60) -> 0.49935916 | F60: =F$1 + SUM($E$2:E60) -> 48.742589 | G60: =F60 * ($G$1/12) -> 0.016775575 | H60: =F60 - G60 -> 48.725814 | I60: =H60 * D60 -> 5854.6014
A61: =COUNTA(A3:A60) -> 58 | B61: =AVERAGE(B3:B60) -> 965.51724 | C61: =SUM(C1:C60) -> 5360 | D61: =AVERAGE(D1:D60) -> 115.49936 | E61: =SUM(E1:E60) -> 48.742589 | F61: =F60 -> 48.742589 | G61: =AVERAGE(G3:G60) -> 0.011899874 | H61: =H60 -> 48.725814 | I61: =I60 -> 5854.6014
A74: Datums | B74: Plusma | C74: Izdevumi
A75: =DATE(2018,1,1) -> 43101 | B75: =-C1-C3 -> -2048 | C75: =(H3-F3)*D3 -> -0.70485333
A76: =EDATE(A75,1) -> 43132 | B76: =-C4 -> -48 | C76: =(H4-F4)*D4 -> -0.71974433
A77: =EDATE(A76,1) -> 43160 | B77: =-C5 -> -48 | C77: =(H5-F5)*D5 -> -0.7316811
A78: =EDATE(A77,1) -> 43191 | B78: =-C6 -> -48 | C78: =(H6-F6)*D6 -> -0.73178925
A79: =EDATE(A78,1) -> 43221 | B79: =-C7 -> -48 | C79: =(H7-F7)*D7 -> -0.75843132
A80: =EDATE(A79,1) -> 43252 | B80: =-C8 -> -48 | C80: =(H8-F8)*D8 -> -0.79946484
A81: =EDATE(A80,1) -> 43282 | B81: =-C9 -> -48 | C81: =(H9-F9)*D9 -> -0.81372905
A82: =EDATE(A81,1) -> 43313 | B82: =-C10 -> -48 | C82: =(H10-F10)*D10 -> -0.83795582
A83: =EDATE(A82,1) -> 43344 | B83: =-C11 -> -48 | C83: =(H11-F11)*D11 -> -0.86277345
A84: =EDATE(A83,1) -> 43374 | B84: =-C12 -> -48 | C84: =(H12-F12)*D12 -> -0.87917825
A85: =EDATE(A84,1) -> 43405 | B85: =-C13 -> -48 | C85: =(H13-F13)*D13 -> -0.87328037
...
